Error during API call for sampled_testcase\TC-5\chunk_60s\4FEN95kaPIo_noisy_25_4FEN95kaPIo.whisper.auto.gt_audio_4.mp3 (Lang: yue-Hant-HK): 400 Sync input too long. For audio longer than 1 min use LongRunningRecognize with a 'uri' parameter.
Traceback (most recent call last):
  File "D:\work\HSBC\stt_benchmark\google_batch_stt.py", line 204, in transcribe_audio_file
    response = client.recognize(config=config, audio=audio_input)
               ^^^^^^^^^^^^^^^^^^^^^^^^^^^^^^^^^^^^^^^^^^^^^^^^^^
  File "c:\Users\User\anaconda3\envs\stt\Lib\site-packages\google\cloud\speech_v1\services\speech\client.py", line 848, in recognize
    response = rpc(
               ^^^^
  File "c:\Users\User\anaconda3\envs\stt\Lib\site-packages\google\api_core\gapic_v1\method.py", line 131, in __call__
    return wrapped_func(*args, **kwargs)
           ^^^^^^^^^^^^^^^^^^^^^^^^^^^^^
  File "c:\Users\User\anaconda3\envs\stt\Lib\site-packages\google\api_core\retry\retry_unary.py", line 293, in retry_wrapped_func
    return retry_target(
           ^^^^^^^^^^^^^
  File "c:\Users\User\anaconda3\envs\stt\Lib\site-packages\google\api_core\retry\retry_unary.py", line 153, in retry_target
    _retry_error_helper(
  File "c:\Users\User\anaconda3\envs\stt\Lib\site-packages\google\api_core\retry\retry_base.py", line 212, in _retry_error_helper
    raise final_exc from source_exc
  File "c:\Users\User\anaconda3\envs\stt\Lib\site-packages\google\api_core\retry\retry_unary.py", line 144, in retry_target
    result = target()
             ^^^^^^^^
  File "c:\Users\User\anaconda3\envs\stt\Lib\site-packages\google\api_core\timeout.py", line 130, in func_with_timeout
    return func(*args, **kwargs)
           ^^^^^^^^^^^^^^^^^^^^^
  File "c:\Users\User\anaconda3\envs\stt\Lib\site-packages\google\api_core\grpc_helpers.py", line 78, in error_remapped_callable
    raise exceptions.from_grpc_error(exc) from exc
google.api_core.exceptions.InvalidArgument: 400 Sync input too long. For audio longer than 1 min use LongRunningRecognize with a 'uri' parameter.
